#usda 1.0
(
    metersPerUnit = 1
    upAxis = "Z"
)

def "World"
{
    def Xform "Plant_1"
    {
        def Xform "Stem"
        {
            def Cylinder "Internode_r0" (
                prepend apiSchemas = ["PhysicsRigidBodyAPI", "PhysicsMassAPI", "PhysicsCollisionAPI"]
            )
            {
                uniform token axis = "Z"
                double height = 0.009268469
                rel material:binding = </World/Plant_1/Materials/Stem>
                float physics:mass = 0.00027164095
                double radius = 0.00321956669808575
                matrix4d xformOp:transform = ( (1, 0, 0, 0), (0, 1, 0, 0), (0, 0, 1, 0), (0, 0, 0.0046342345, 1) )
                uniform token[] xformOpOrder = ["xformOp:transform"]
            }

            def Cylinder "Internode_r1" (
                prepend apiSchemas = ["PhysicsRigidBodyAPI", "PhysicsMassAPI", "PhysicsCollisionAPI"]
            )
            {
                uniform token axis = "Z"
                double height = 0.010035751
                rel material:binding = </World/Plant_1/Materials/Stem>
                float physics:mass = 0.00031688114
                double radius = 0.00334177399222325
                matrix4d xformOp:transform = ( (1, 0, 0, 0), (0, 1, 0, 0), (0, 0, 1, 0), (0, 0, 0.033636295499999996, 1) )
                uniform token[] xformOpOrder = ["xformOp:transform"]
            }

            def Cylinder "Internode_r2" (
                prepend apiSchemas = ["PhysicsRigidBodyAPI", "PhysicsMassAPI", "PhysicsCollisionAPI"]
            )
            {
                uniform token axis = "Z"
                double height = 0.016825004
                rel material:binding = </World/Plant_1/Materials/Stem>
                float physics:mass = 0.00086203986
                double radius = 0.0042568651546112
                matrix4d xformOp:transform = ( (1, 0, 0, 0), (0, 1, 0, 0), (0, 0, 1, 0), (0, 0, 0.063105705, 1) )
                uniform token[] xformOpOrder = ["xformOp:transform"]
            }

            def Cylinder "Internode_r3" (
                prepend apiSchemas = ["PhysicsRigidBodyAPI", "PhysicsMassAPI", "PhysicsCollisionAPI"]
            )
            {
                uniform token axis = "Z"
                double height = 0.016922036
                rel material:binding = </World/Plant_1/Materials/Stem>
                float physics:mass = 0.0008716948
                double radius = 0.00426834715371355
                matrix4d xformOp:transform = ( (1, 0, 0, 0), (0, 1, 0, 0), (0, 0, 1, 0), (0, 0, 0.079979225, 1) )
                uniform token[] xformOpOrder = ["xformOp:transform"]
            }

            def Cylinder "Internode_r4" (
                prepend apiSchemas = ["PhysicsRigidBodyAPI", "PhysicsMassAPI", "PhysicsCollisionAPI"]
            )
            {
                uniform token axis = "Z"
                double height = 0.016329734
                rel material:binding = </World/Plant_1/Materials/Stem>
                float physics:mass = 0.00081357046
                double radius = 0.00419770428228965
                matrix4d xformOp:transform = ( (1, 0, 0, 0), (0, 1, 0, 0), (0, 0, 1, 0), (0, 0, 0.09660511, 1) )
                uniform token[] xformOpOrder = ["xformOp:transform"]
            }

            def Cylinder "Internode_r5" (
                prepend apiSchemas = ["PhysicsRigidBodyAPI", "PhysicsMassAPI", "PhysicsCollisionAPI"]
            )
            {
                uniform token axis = "Z"
                double height = 0.015278612
                rel material:binding = </World/Plant_1/Materials/Stem>
                float physics:mass = 0.00071520504
                double radius = 0.0040689011829778
                matrix4d xformOp:transform = ( (1, 0, 0, 0), (0, 1, 0, 0), (0, 0, 1, 0), (0, 0, 0.112409283, 1) )
                uniform token[] xformOpOrder = ["xformOp:transform"]
            }

            def Cylinder "Internode_r6" (
                prepend apiSchemas = ["PhysicsRigidBodyAPI", "PhysicsMassAPI", "PhysicsCollisionAPI"]
            )
            {
                uniform token axis = "Z"
                double height = 0.031820413
                rel material:binding = </World/Plant_1/Materials/Stem>
                float physics:mass = 0.0013603277
                double radius = 0.00388841560915925
                matrix4d xformOp:transform = ( (1, 0, 0, 0), (0, 1, 0, 0), (0, 0, 1, 0), (0, 0, 0.1359587955, 1) )
                uniform token[] xformOpOrder = ["xformOp:transform"]
            }

            def Cylinder "Internode_r7" (
                prepend apiSchemas = ["PhysicsRigidBodyAPI", "PhysicsMassAPI", "PhysicsCollisionAPI"]
            )
            {
                uniform token axis = "Z"
                double height = 0.026539747
                rel material:binding = </World/Plant_1/Materials/Stem>
                float physics:mass = 0.00093960884
                double radius = 0.00353857962761135
                matrix4d xformOp:transform = ( (1, 0, 0, 0), (0, 1, 0, 0), (0, 0, 1, 0), (0, 0, 0.1651388755, 1) )
                uniform token[] xformOpOrder = ["xformOp:transform"]
            }

            def Cylinder "Internode_r8" (
                prepend apiSchemas = ["PhysicsRigidBodyAPI", "PhysicsMassAPI", "PhysicsCollisionAPI"]
            )
            {
                uniform token axis = "Z"
                double height = 0.012889969
                rel material:binding = </World/Plant_1/Materials/Stem>
                float physics:mass = 0.0002154795
                double radius = 0.0024315368033847
                matrix4d xformOp:transform = ( (1, 0, 0, 0), (0, 1, 0, 0), (0, 0, 1, 0), (0, 0, 0.1848537335, 1) )
                uniform token[] xformOpOrder = ["xformOp:transform"]
            }
        }

        def Xform "Roots"
        {
            def Sphere "Root"
            {
                rel material:binding = </World/Plant_1/Materials/Root>
                double radius = 0.005
                matrix4d xformOp:transform = ( (1, 0, 0, 0), (0, 1, 0, 0), (0, 0, 1, 0), (0, 0, -0.005, 1) )
                uniform token[] xformOpOrder = ["xformOp:transform"]
            }
        }

        def Xform "Materials"
        {
            def Material "Stem"
            {
                token outputs:surface.connect = </World/Plant_1/Materials/Stem/Shader.outputs:surface>

                def Shader "Shader"
                {
                    uniform token info:id = "UsdPreviewSurface"
                    color3f inputs:diffuseColor = (0.45, 0.3, 0.1)
                    float inputs:metallic = 0
                    float inputs:roughness = 0.6
                    token outputs:surface
                }
            }

            def Material "Root"
            {
                token outputs:surface.connect = </World/Plant_1/Materials/Root/Shader.outputs:surface>

                def Shader "Shader"
                {
                    uniform token info:id = "UsdPreviewSurface"
                    color3f inputs:diffuseColor = (0.55, 0.35, 0.15)
                    float inputs:metallic = 0
                    float inputs:roughness = 0.6
                    token outputs:surface
                }
            }

            def Material "Leaf"
            {
                token outputs:surface.connect = </World/Plant_1/Materials/Leaf/Shader.outputs:surface>

                def Shader "Shader"
                {
                    uniform token info:id = "UsdPreviewSurface"
                    color3f inputs:diffuseColor = (0.15, 0.55, 0.1)
                    float inputs:metallic = 0
                    float inputs:roughness = 0.6
                    token outputs:surface
                }
            }

            def Material "Pedicel"
            {
                token outputs:surface.connect = </World/Plant_1/Materials/Pedicel/Shader.outputs:surface>

                def Shader "Shader"
                {
                    uniform token info:id = "UsdPreviewSurface"
                    color3f inputs:diffuseColor = (0.2, 0.5, 0.1)
                    float inputs:metallic = 0
                    float inputs:roughness = 0.6
                    token outputs:surface
                }
            }

            def Material "Fruit"
            {
                token outputs:surface.connect = </World/Plant_1/Materials/Fruit/Shader.outputs:surface>

                def Shader "Shader"
                {
                    uniform token info:id = "UsdPreviewSurface"
                    color3f inputs:diffuseColor = (0.9, 0.15, 0.05)
                    float inputs:metallic = 0
                    float inputs:roughness = 0.6
                    token outputs:surface
                }
            }
        }

        def Xform "Joints"
        {
            def PhysicsFixedJoint "GroundAnchor"
            {
                rel physics:body1 = </World/Plant_1/Stem/Internode_r0>
            }

            def PhysicsSphericalJoint "Joint_r1" (
                prepend apiSchemas = ["PhysicsDriveAPI:rotX", "PhysicsDriveAPI:rotY"]
            )
            {
                float drive:rotX:physics:damping = 50
                float drive:rotX:physics:stiffness = 680
                float drive:rotX:physics:targetPosition = 0
                uniform token drive:rotX:physics:type = "force"
                float drive:rotY:physics:damping = 50
                float drive:rotY:physics:stiffness = 680
                float drive:rotY:physics:targetPosition = 0
                uniform token drive:rotY:physics:type = "force"
                rel physics:body0 = </World/Plant_1/Stem/Internode_r1>
                rel physics:body1 = </World/Plant_1/Stem/Internode_r1>
                float physics:coneAngle0Limit = 25
                float physics:coneAngle1Limit = 25
                point3f physics:localPos0 = (0, 0, 0.009674976)
                point3f physics:localPos1 = (0, 0, 0)
            }

            def PhysicsSphericalJoint "Joint_r2" (
                prepend apiSchemas = ["PhysicsDriveAPI:rotX", "PhysicsDriveAPI:rotY"]
            )
            {
                float drive:rotX:physics:damping = 50
                float drive:rotX:physics:stiffness = 560
                float drive:rotX:physics:targetPosition = 0
                uniform token drive:rotX:physics:type = "force"
                float drive:rotY:physics:damping = 50
                float drive:rotY:physics:stiffness = 560
                float drive:rotY:physics:targetPosition = 0
                uniform token drive:rotY:physics:type = "force"
                rel physics:body0 = </World/Plant_1/Stem/Internode_r2>
                rel physics:body1 = </World/Plant_1/Stem/Internode_r2>
                float physics:coneAngle0Limit = 25
                float physics:coneAngle1Limit = 25
                point3f physics:localPos0 = (0, 0, 0.008019516)
                point3f physics:localPos1 = (0, 0, 0)
            }

            def PhysicsSphericalJoint "Joint_r3" (
                prepend apiSchemas = ["PhysicsDriveAPI:rotX", "PhysicsDriveAPI:rotY"]
            )
            {
                float drive:rotX:physics:damping = 50
                float drive:rotX:physics:stiffness = 500
                float drive:rotX:physics:targetPosition = 0
                uniform token drive:rotX:physics:type = "force"
                float drive:rotY:physics:damping = 50
                float drive:rotY:physics:stiffness = 500
                float drive:rotY:physics:targetPosition = 0
                uniform token drive:rotY:physics:type = "force"
                rel physics:body0 = </World/Plant_1/Stem/Internode_r2>
                rel physics:body1 = </World/Plant_1/Stem/Internode_r3>
                float physics:coneAngle0Limit = 25
                float physics:coneAngle1Limit = 25
                point3f physics:localPos0 = (0, 0, 0.008412502)
                point3f physics:localPos1 = (0, 0, 0)
            }

            def PhysicsSphericalJoint "Joint_r4" (
                prepend apiSchemas = ["PhysicsDriveAPI:rotX", "PhysicsDriveAPI:rotY"]
            )
            {
                float drive:rotX:physics:damping = 50
                float drive:rotX:physics:stiffness = 440
                float drive:rotX:physics:targetPosition = 0
                uniform token drive:rotX:physics:type = "force"
                float drive:rotY:physics:damping = 50
                float drive:rotY:physics:stiffness = 440
                float drive:rotY:physics:targetPosition = 0
                uniform token drive:rotY:physics:type = "force"
                rel physics:body0 = </World/Plant_1/Stem/Internode_r3>
                rel physics:body1 = </World/Plant_1/Stem/Internode_r4>
                float physics:coneAngle0Limit = 25
                float physics:coneAngle1Limit = 25
                point3f physics:localPos0 = (0, 0, 0.008461018)
                point3f physics:localPos1 = (0, 0, 0)
            }

            def PhysicsSphericalJoint "Joint_r5" (
                prepend apiSchemas = ["PhysicsDriveAPI:rotX", "PhysicsDriveAPI:rotY"]
            )
            {
                float drive:rotX:physics:damping = 50
                float drive:rotX:physics:stiffness = 380
                float drive:rotX:physics:targetPosition = 0
                uniform token drive:rotX:physics:type = "force"
                float drive:rotY:physics:damping = 50
                float drive:rotY:physics:stiffness = 380
                float drive:rotY:physics:targetPosition = 0
                uniform token drive:rotY:physics:type = "force"
                rel physics:body0 = </World/Plant_1/Stem/Internode_r4>
                rel physics:body1 = </World/Plant_1/Stem/Internode_r5>
                float physics:coneAngle0Limit = 25
                float physics:coneAngle1Limit = 25
                point3f physics:localPos0 = (0, 0, 0.008164867)
                point3f physics:localPos1 = (0, 0, 0)
            }

            def PhysicsSphericalJoint "Joint_r6" (
                prepend apiSchemas = ["PhysicsDriveAPI:rotX", "PhysicsDriveAPI:rotY"]
            )
            {
                float drive:rotX:physics:damping = 50
                float drive:rotX:physics:stiffness = 320
                float drive:rotX:physics:targetPosition = 0
                uniform token drive:rotX:physics:type = "force"
                float drive:rotY:physics:damping = 50
                float drive:rotY:physics:stiffness = 320
                float drive:rotY:physics:targetPosition = 0
                uniform token drive:rotY:physics:type = "force"
                rel physics:body0 = </World/Plant_1/Stem/Internode_r5>
                rel physics:body1 = </World/Plant_1/Stem/Internode_r6>
                float physics:coneAngle0Limit = 25
                float physics:coneAngle1Limit = 25
                point3f physics:localPos0 = (0, 0, 0.007639306)
                point3f physics:localPos1 = (0, 0, 0)
            }

            def PhysicsSphericalJoint "Joint_r7" (
                prepend apiSchemas = ["PhysicsDriveAPI:rotX", "PhysicsDriveAPI:rotY"]
            )
            {
                float drive:rotX:physics:damping = 50
                float drive:rotX:physics:stiffness = 260
                float drive:rotX:physics:targetPosition = 0
                uniform token drive:rotX:physics:type = "force"
                float drive:rotY:physics:damping = 50
                float drive:rotY:physics:stiffness = 260
                float drive:rotY:physics:targetPosition = 0
                uniform token drive:rotY:physics:type = "force"
                rel physics:body0 = </World/Plant_1/Stem/Internode_r6>
                rel physics:body1 = </World/Plant_1/Stem/Internode_r7>
                float physics:coneAngle0Limit = 25
                float physics:coneAngle1Limit = 25
                point3f physics:localPos0 = (0, 0, 0.015910206)
                point3f physics:localPos1 = (0, 0, 0)
            }

            def PhysicsSphericalJoint "Joint_r8" (
                prepend apiSchemas = ["PhysicsDriveAPI:rotX", "PhysicsDriveAPI:rotY"]
            )
            {
                float drive:rotX:physics:damping = 50
                float drive:rotX:physics:stiffness = 200
                float drive:rotX:physics:targetPosition = 0
                uniform token drive:rotX:physics:type = "force"
                float drive:rotY:physics:damping = 50
                float drive:rotY:physics:stiffness = 200
                float drive:rotY:physics:targetPosition = 0
                uniform token drive:rotY:physics:type = "force"
                rel physics:body0 = </World/Plant_1/Stem/Internode_r7>
                rel physics:body1 = </World/Plant_1/Stem/Internode_r8>
                float physics:coneAngle0Limit = 25
                float physics:coneAngle1Limit = 25
                point3f physics:localPos0 = (0, 0, 0.013269873)
                point3f physics:localPos1 = (0, 0, 0)
            }
        }

        def Xform "Leaves"
        {
            def Xform "Leaf_r8_i0"
            {
                def Cylinder "Petiole"
                {
                    uniform token axis = "Z"
                    double height = 0.010315108
                    rel material:binding = </World/Plant_1/Materials/Leaf>
                    double radius = 0.0010667109
                    matrix4d xformOp:transform = ( (0, 1, 0, 0), (-0.3420201433256687, 0, 0.9396926207859084, 0), (0.9396926207859084, 0, 0.3420201433256687, 0), (0.004846515435104845, 0, 0.19306270535828987, 1) )
                    uniform token[] xformOpOrder = ["xformOp:transform"]
                }

                def Cylinder "Rachis"
                {
                    uniform token axis = "Z"
                    double height = 0.025914127
                    rel material:binding = </World/Plant_1/Materials/Leaf>
                    double radius = 0.00064002654
                    matrix4d xformOp:transform = ( (0, 1, 0, 0), (-0.3420201433256687, 0, 0.9396926207859084, 0), (0.9396926207859084, 0, 0.3420201433256687, 0), (0.021868687828214127, 0, 0.19925826943192956, 1) )
                    uniform token[] xformOpOrder = ["xformOp:transform"]
                }

                def Mesh "Blade_0"
                {
                    int[] faceVertexCounts = [3, 3]
                    int[] faceVertexIndices = [0, 1, 2, 0, 2, 3]
                    rel material:binding = </World/Plant_1/Materials/Leaf>
                    point3f[] points = [(-0.0005789244, -0.00096487394, 0), (0.0005789244, -0.00096487394, 0), (0.0005789244, 0.00096487394, 0), (-0.0005789244, 0.00096487394, 0)]
                    uniform token subdivisionScheme = "none"
                    matrix4d xformOp:transform = ( (-0.7287394448186828, -0.6847910787717361, 0, 0), (-0.16561313590900145, 0.17624181806439163, 0.9703149544244614, 0), (-0.6644630243886748, 0.7071067811865475, -0.24184476264797528, 0), (0.009051907832278923, 0.0006822688863881551, 0.19459334301427064, 1) )
                    uniform token[] xformOpOrder = ["xformOp:transform"]
                }

                def Mesh "Blade_1"
                {
                    int[] faceVertexCounts = [3, 3]
                    int[] faceVertexIndices = [0, 1, 2, 0, 2, 3]
                    rel material:binding = </World/Plant_1/Materials/Leaf>
                    point3f[] points = [(-0.0005789244, -0.00096487394, 0), (0.0005789244, -0.00096487394, 0), (0.0005789244, 0.00096487394, 0), (-0.0005789244, 0.00096487394, 0)]
                    uniform token subdivisionScheme = "none"
                    matrix4d xformOp:transform = ( (0.7287394448186828, -0.6847910787717361, 0, 0), (-0.16561313590900145, -0.17624181806439163, 0.9703149544244614, 0), (-0.6644630243886748, -0.7071067811865475, -0.24184476264797528, 0), (0.01716901247094854, -0.0006822688863881551, 0.1975477274911705, 1) )
                    uniform token[] xformOpOrder = ["xformOp:transform"]
                }

                def Mesh "Blade_2"
                {
                    int[] faceVertexCounts = [3, 3]
                    int[] faceVertexIndices = [0, 1, 2, 0, 2, 3]
                    rel material:binding = </World/Plant_1/Materials/Leaf>
                    point3f[] points = [(-0.0005789244, -0.00096487394, 0), (0.0005789244, -0.00096487394, 0), (0.0005789244, 0.00096487394, 0), (-0.0005789244, 0.00096487394, 0)]
                    uniform token subdivisionScheme = "none"
                    matrix4d xformOp:transform = ( (-0.7287394448186828, -0.6847910787717361, 0, 0), (-0.16561313590900145, 0.17624181806439163, 0.9703149544244614, 0), (-0.6644630243886748, 0.7071067811865475, -0.24184476264797528, 0), (0.025286117109618166, 0.0006822688863881551, 0.20050211196807036, 1) )
                    uniform token[] xformOpOrder = ["xformOp:transform"]
                }

                def Mesh "Blade_3"
                {
                    int[] faceVertexCounts = [3, 3]
                    int[] faceVertexIndices = [0, 1, 2, 0, 2, 3]
                    rel material:binding = </World/Plant_1/Materials/Leaf>
                    point3f[] points = [(-0.0005789244, -0.00096487394, 0), (0.0005789244, -0.00096487394, 0), (0.0005789244, 0.00096487394, 0), (-0.0005789244, 0.00096487394, 0)]
                    uniform token subdivisionScheme = "none"
                    matrix4d xformOp:transform = ( (0, -1, 0, 0), (0.9396926207859084, 0, 0.3420201433256687, 0), (-0.3420201433256687, 0, 0.9396926207859084, 0), (0.03404434478621856, 0, 0.20368984614727934, 1) )
                    uniform token[] xformOpOrder = ["xformOp:transform"]
                }
            }

            def Xform "Leaf_r7_i0"
            {
                def Cylinder "Petiole"
                {
                    uniform token axis = "Z"
                    double height = 0.022824008
                    rel material:binding = </World/Plant_1/Materials/Leaf>
                    double radius = 0.002019096
                    matrix4d xformOp:transform = ( (0, 1, 0, 0), (-0.3420201433256687, 0, 0.9396926207859084, 0), (0.9396926207859084, 0, 0.3420201433256687, 0), (0.01072377594717927, 0, 0.1823118842437131, 1) )
                    uniform token[] xformOpOrder = ["xformOp:transform"]
                }

                def Cylinder "Rachis"
                {
                    uniform token axis = "Z"
                    double height = 0.07816507
                    rel material:binding = </World/Plant_1/Materials/Leaf>
                    double radius = 0.0012114576
                    matrix4d xformOp:transform = ( (0, 1, 0, 0), (-0.3420201433256687, 0, 0.9396926207859084, 0), (0.9396926207859084, 0, 0.3420201433256687, 0), (0.058173121635465536, 0, 0.1995820337096567, 1) )
                    uniform token[] xformOpOrder = ["xformOp:transform"]
                }

                def Mesh "Blade_0"
                {
                    int[] faceVertexCounts = [3, 3]
                    int[] faceVertexIndices = [0, 1, 2, 0, 2, 3]
                    rel material:binding = </World/Plant_1/Materials/Leaf>
                    point3f[] points = [(-0.005586289, -0.009310482, 0), (0.005586289, -0.009310482, 0), (0.005586289, 0.009310482, 0), (-0.005586289, 0.009310482, 0)]
                    uniform token subdivisionScheme = "none"
                    matrix4d xformOp:transform = ( (-0.7287394448186828, -0.6847910787717361, 0, 0), (-0.16561313590900145, 0.17624181806439163, 0.9703149544244614, 0), (-0.6644630243886748, 0.7071067811865475, -0.24184476264797528, 0), (0.015261081128895924, 0.006583504678677359, 0.1839633282736398, 1) )
                    uniform token[] xformOpOrder = ["xformOp:transform"]
                }

                def Mesh "Blade_1"
                {
                    int[] faceVertexCounts = [3, 3]
                    int[] faceVertexIndices = [0, 1, 2, 0, 2, 3]
                    rel material:binding = </World/Plant_1/Materials/Leaf>
                    point3f[] points = [(-0.005586289, -0.009310482, 0), (0.005586289, -0.009310482, 0), (0.005586289, 0.009310482, 0), (-0.005586289, 0.009310482, 0)]
                    uniform token subdivisionScheme = "none"
                    matrix4d xformOp:transform = ( (0.7287394448186828, -0.6847910787717361, 0, 0), (-0.16561313590900145, -0.17624181806439163, 0.9703149544244614, 0), (-0.6644630243886748, -0.7071067811865475, -0.24184476264797528, 0), (0.03974479428963392, -0.006583504678677359, 0.1928746710884601, 1) )
                    uniform token[] xformOpOrder = ["xformOp:transform"]
                }

                def Mesh "Blade_2"
                {
                    int[] faceVertexCounts = [3, 3]
                    int[] faceVertexIndices = [0, 1, 2, 0, 2, 3]
                    rel material:binding = </World/Plant_1/Materials/Leaf>
                    point3f[] points = [(-0.005586289, -0.009310482, 0), (0.005586289, -0.009310482, 0), (0.005586289, 0.009310482, 0), (-0.005586289, 0.009310482, 0)]
                    uniform token subdivisionScheme = "none"
                    matrix4d xformOp:transform = ( (-0.7287394448186828, -0.6847910787717361, 0, 0), (-0.16561313590900145, 0.17624181806439163, 0.9703149544244614, 0), (-0.6644630243886748, 0.7071067811865475, -0.24184476264797528, 0), (0.06422850745037191, 0.006583504678677359, 0.2017860139032804, 1) )
                    uniform token[] xformOpOrder = ["xformOp:transform"]
                }

                def Mesh "Blade_3"
                {
                    int[] faceVertexCounts = [3, 3]
                    int[] faceVertexIndices = [0, 1, 2, 0, 2, 3]
                    rel material:binding = </World/Plant_1/Materials/Leaf>
                    point3f[] points = [(-0.005586289, -0.009310482, 0), (0.005586289, -0.009310482, 0), (0.005586289, 0.009310482, 0), (-0.005586289, 0.009310482, 0)]
                    uniform token subdivisionScheme = "none"
                    matrix4d xformOp:transform = ( (0, -1, 0, 0), (0.9396926207859084, 0, 0.3420201433256687, 0), (-0.3420201433256687, 0, 0.9396926207859084, 0), (0.09489869137657253, 0, 0.21294904793188715, 1) )
                    uniform token[] xformOpOrder = ["xformOp:transform"]
                }
            }

            def Xform "Leaf_r6_i0"
            {
                def Cylinder "Petiole"
                {
                    uniform token axis = "Z"
                    double height = 0.0278836
                    rel material:binding = </World/Plant_1/Materials/Leaf>
                    double radius = 0.00237147675
                    matrix4d xformOp:transform = ( (0, 1, 0, 0), (-0.3420201433256687, 0, 0.9396926207859084, 0), (0.9396926207859084, 0, 0.3420201433256687, 0), (0.013101006580472979, 0, 0.15663737843421782, 1) )
                    uniform token[] xformOpOrder = ["xformOp:transform"]
                }

                def Cylinder "Rachis"
                {
                    uniform token axis = "Z"
                    double height = 0.10442752
                    rel material:binding = </World/Plant_1/Materials/Leaf>
                    double radius = 0.00142288605
                    matrix4d xformOp:transform = ( (0, 1, 0, 0), (-0.3420201433256687, 0, 0.9396926207859084, 0), (0.9396926207859084, 0, 0.3420201433256687, 0), (0.07526689813643239, 0, 0.1792639125472077, 1) )
                    uniform token[] xformOpOrder = ["xformOp:transform"]
                }

                def Mesh "Blade_0"
                {
                    int[] faceVertexCounts = [3, 3]
                    int[] faceVertexIndices = [0, 1, 2, 0, 2, 3]
                    rel material:binding = </World/Plant_1/Materials/Leaf>
                    point3f[] points = [(-0.009892932, -0.01648822, 0), (0.009892932, -0.01648822, 0), (0.009892932, 0.01648822, 0), (-0.009892932, 0.01648822, 0)]
                    uniform token subdivisionScheme = "none"
                    matrix4d xformOp:transform = ( (-0.7287394448186828, -0.6847910787717361, 0, 0), (-0.16561313590900145, 0.17624181806439163, 0.9703149544244614, 0), (-0.6644630243886748, 0.7071067811865475, -0.24184476264797528, 0), (0.015246200482208662, 0.01165893233212201, 0.15741816516117896, 1) )
                    uniform token[] xformOpOrder = ["xformOp:transform"]
                }

                def Mesh "Blade_1"
                {
                    int[] faceVertexCounts = [3, 3]
                    int[] faceVertexIndices = [0, 1, 2, 0, 2, 3]
                    rel material:binding = </World/Plant_1/Materials/Leaf>
                    point3f[] points = [(-0.009892932, -0.01648822, 0), (0.009892932, -0.01648822, 0), (0.009892932, 0.01648822, 0), (-0.009892932, 0.01648822, 0)]
                    uniform token subdivisionScheme = "none"
                    matrix4d xformOp:transform = ( (0.7287394448186828, -0.6847910787717361, 0, 0), (-0.16561313590900145, -0.17624181806439163, 0.9703149544244614, 0), (-0.6644630243886748, -0.7071067811865475, -0.24184476264797528, 0), (0.04795612379919961, -0.01165893233212201, 0.16932360361369367, 1) )
                    uniform token[] xformOpOrder = ["xformOp:transform"]
                }

                def Mesh "Blade_2"
                {
                    int[] faceVertexCounts = [3, 3]
                    int[] faceVertexIndices = [0, 1, 2, 0, 2, 3]
                    rel material:binding = </World/Plant_1/Materials/Leaf>
                    point3f[] points = [(-0.009892932, -0.01648822, 0), (0.009892932, -0.01648822, 0), (0.009892932, 0.01648822, 0), (-0.009892932, 0.01648822, 0)]
                    uniform token subdivisionScheme = "none"
                    matrix4d xformOp:transform = ( (-0.7287394448186828, -0.6847910787717361, 0, 0), (-0.16561313590900145, 0.17624181806439163, 0.9703149544244614, 0), (-0.6644630243886748, 0.7071067811865475, -0.24184476264797528, 0), (0.08066604711619056, 0.01165893233212201, 0.18122904206620838, 1) )
                    uniform token[] xformOpOrder = ["xformOp:transform"]
                }

                def Mesh "Blade_3"
                {
                    int[] faceVertexCounts = [3, 3]
                    int[] faceVertexIndices = [0, 1, 2, 0, 2, 3]
                    rel material:binding = </World/Plant_1/Materials/Leaf>
                    point3f[] points = [(-0.009892932, -0.01648822, 0), (0.009892932, -0.01648822, 0), (0.009892932, 0.01648822, 0), (-0.009892932, 0.01648822, 0)]
                    uniform token subdivisionScheme = "none"
                    matrix4d xformOp:transform = ( (0, -1, 0, 0), (0.9396926207859084, 0, 0.3420201433256687, 0), (-0.3420201433256687, 0, 0.9396926207859084, 0), (0.12433178311191882, 0, 0.19712207022597975, 1) )
                    uniform token[] xformOpOrder = ["xformOp:transform"]
                }
            }

            def Xform "Leaf_r5_i0"
            {
                def Cylinder "Petiole"
                {
                    uniform token axis = "Z"
                    double height = 0.030694524
                    rel material:binding = </World/Plant_1/Materials/Leaf>
                    double radius = 0.0025617145
                    matrix4d xformOp:transform = ( (0, 1, 0, 0), (-0.3420201433256687, 0, 0.9396926207859084, 0), (0.9396926207859084, 0, 0.3420201433256687, 0), (0.014421708850667982, 0, 0.1252976617488966, 1) )
                    uniform token[] xformOpOrder = ["xformOp:transform"]
                }

                def Cylinder "Rachis"
                {
                    uniform token axis = "Z"
                    double height = 0.12017747
                    rel material:binding = </World/Plant_1/Materials/Leaf>
                    double radius = 0.0015370286999999998
                    matrix4d xformOp:transform = ( (0, 1, 0, 0), (-0.3420201433256687, 0, 0.9396926207859084, 0), (0.9396926207859084, 0, 0.3420201433256687, 0), (0.08530835857319591, 0, 0.1510982922547513, 1) )
                    uniform token[] xformOpOrder = ["xformOp:transform"]
                }

                def Mesh "Blade_0"
                {
                    int[] faceVertexCounts = [3, 3]
                    int[] faceVertexIndices = [0, 1, 2, 0, 2, 3]
                    rel material:binding = </World/Plant_1/Materials/Leaf>
                    point3f[] points = [(-0.013013196, -0.02168866, 0), (0.013013196, -0.02168866, 0), (0.013013196, 0.02168866, 0), (-0.013013196, 0.02168866, 0)]
                    uniform token subdivisionScheme = "none"
                    matrix4d xformOp:transform = ( (-0.7287394448186828, -0.6847910787717361, 0, 0), (-0.16561313590900145, 0.17624181806439163, 0.9703149544244614, 0), (-0.6644630243886748, 0.7071067811865475, -0.24184476264797528, 0), (0.014432104982141293, 0.015336198667966363, 0.12530144563130438, 1) )
                    uniform token[] xformOpOrder = ["xformOp:transform"]
                }

                def Mesh "Blade_1"
                {
                    int[] faceVertexCounts = [3, 3]
                    int[] faceVertexIndices = [0, 1, 2, 0, 2, 3]
                    rel material:binding = </World/Plant_1/Materials/Leaf>
                    point3f[] points = [(-0.013013196, -0.02168866, 0), (0.013013196, -0.02168866, 0), (0.013013196, 0.02168866, 0), (-0.013013196, 0.02168866, 0)]
                    uniform token subdivisionScheme = "none"
                    matrix4d xformOp:transform = ( (0.7287394448186828, -0.6847910787717361, 0, 0), (-0.16561313590900145, -0.17624181806439163, 0.9703149544244614, 0), (-0.6644630243886748, -0.7071067811865475, -0.24184476264797528, 0), (0.052075398896714586, -0.015336198667966363, 0.13900248413594313, 1) )
                    uniform token[] xformOpOrder = ["xformOp:transform"]
                }

                def Mesh "Blade_2"
                {
                    int[] faceVertexCounts = [3, 3]
                    int[] faceVertexIndices = [0, 1, 2, 0, 2, 3]
                    rel material:binding = </World/Plant_1/Materials/Leaf>
                    point3f[] points = [(-0.013013196, -0.02168866, 0), (0.013013196, -0.02168866, 0), (0.013013196, 0.02168866, 0), (-0.013013196, 0.02168866, 0)]
                    uniform token subdivisionScheme = "none"
                    matrix4d xformOp:transform = ( (-0.7287394448186828, -0.6847910787717361, 0, 0), (-0.16561313590900145, 0.17624181806439163, 0.9703149544244614, 0), (-0.6644630243886748, 0.7071067811865475, -0.24184476264797528, 0), (0.08971869281128787, 0.015336198667966363, 0.15270352264058187, 1) )
                    uniform token[] xformOpOrder = ["xformOp:transform"]
                }

                def Mesh "Blade_3"
                {
                    int[] faceVertexCounts = [3, 3]
                    int[] faceVertexIndices = [0, 1, 2, 0, 2, 3]
                    rel material:binding = </World/Plant_1/Materials/Leaf>
                    point3f[] points = [(-0.013013196, -0.02168866, 0), (0.013013196, -0.02168866, 0), (0.013013196, 0.02168866, 0), (-0.013013196, 0.02168866, 0)]
                    uniform token subdivisionScheme = "none"
                    matrix4d xformOp:transform = ( (0, -1, 0, 0), (0.9396926207859084, 0, 0.3420201433256687, 0), (-0.3420201433256687, 0, 0.9396926207859084, 0), (0.14177329944505584, 0, 0.1716498500117094, 1) )
                    uniform token[] xformOpOrder = ["xformOp:transform"]
                }
            }

            def Xform "Leaf_r4_i0"
            {
                def Cylinder "Petiole"
                {
                    uniform token axis = "Z"
                    double height = 0.03275578
                    rel material:binding = </World/Plant_1/Materials/Leaf>
                    double radius = 0.0026990355
                    matrix4d xformOp:transform = ( (0, 1, 0, 0), (-0.3420201433256687, 0, 0.9396926207859084, 0), (0.9396926207859084, 0, 0.3420201433256687, 0), (0.01539018237704332, 0, 0.11037154528517204, 1) )
                    uniform token[] xformOpOrder = ["xformOp:transform"]
                }

                def Cylinder "Rachis"
                {
                    uniform token axis = "Z"
                    double height = 0.1322346
                    rel material:binding = </World/Plant_1/Materials/Leaf>
                    double radius = 0.0016194213
                    matrix4d xformOp:transform = ( (0, 1, 0, 0), (-0.3420201433256687, 0, 0.9396926207859084, 0), (0.9396926207859084, 0, 0.3420201433256687, 0), (0.09291030367037478, 0, 0.1385865619926503, 1) )
                    uniform token[] xformOpOrder = ["xformOp:transform"]
                }

                def Mesh "Blade_0"
                {
                    int[] faceVertexCounts = [3, 3]
                    int[] faceVertexIndices = [0, 1, 2, 0, 2, 3]
                    rel material:binding = </World/Plant_1/Materials/Leaf>
                    point3f[] points = [(-0.015665803, -0.026109671, 0), (0.015665803, -0.026109671, 0), (0.015665803, 0.026109671, 0), (-0.015665803, 0.026109671, 0)]
                    uniform token subdivisionScheme = "none"
                    matrix4d xformOp:transform = ( (-0.7287394448186828, -0.6847910787717361, 0, 0), (-0.16561313590900145, 0.17624181806439163, 0.9703149544244614, 0), (-0.6644630243886748, 0.7071067811865475, -0.24184476264797528, 0), (0.013431454099683209, 0.018462325095086662, 0.10965862649519743, 1) )
                    uniform token[] xformOpOrder = ["xformOp:transform"]
                }

                def Mesh "Blade_1"
                {
                    int[] faceVertexCounts = [3, 3]
                    int[] faceVertexIndices = [0, 1, 2, 0, 2, 3]
                    rel material:binding = </World/Plant_1/Materials/Leaf>
                    point3f[] points = [(-0.015665803, -0.026109671, 0), (0.015665803, -0.026109671, 0), (0.015665803, 0.026109671, 0), (-0.015665803, 0.026109671, 0)]
                    uniform token subdivisionScheme = "none"
                    matrix4d xformOp:transform = ( (0.7287394448186828, -0.6847910787717361, 0, 0), (-0.16561313590900145, -0.17624181806439163, 0.9703149544244614, 0), (-0.6644630243886748, -0.7071067811865475, -0.24184476264797528, 0), (0.05485141337720864, -0.018462325095086662, 0.12473425877673493, 1) )
                    uniform token[] xformOpOrder = ["xformOp:transform"]
                }

                def Mesh "Blade_2"
                {
                    int[] faceVertexCounts = [3, 3]
                    int[] faceVertexIndices = [0, 1, 2, 0, 2, 3]
                    rel material:binding = </World/Plant_1/Materials/Leaf>
                    point3f[] points = [(-0.015665803, -0.026109671, 0), (0.015665803, -0.026109671, 0), (0.015665803, 0.026109671, 0), (-0.015665803, 0.026109671, 0)]
                    uniform token subdivisionScheme = "none"
                    matrix4d xformOp:transform = ( (-0.7287394448186828, -0.6847910787717361, 0, 0), (-0.16561313590900145, 0.17624181806439163, 0.9703149544244614, 0), (-0.6644630243886748, 0.7071067811865475, -0.24184476264797528, 0), (0.09627137265473407, 0.018462325095086662, 0.13980989105827243, 1) )
                    uniform token[] xformOpOrder = ["xformOp:transform"]
                }

                def Mesh "Blade_3"
                {
                    int[] faceVertexCounts = [3, 3]
                    int[] faceVertexIndices = [0, 1, 2, 0, 2, 3]
                    rel material:binding = </World/Plant_1/Materials/Leaf>
                    point3f[] points = [(-0.015665803, -0.026109671, 0), (0.015665803, -0.026109671, 0), (0.015665803, 0.026109671, 0), (-0.015665803, 0.026109671, 0)]
                    uniform token subdivisionScheme = "none"
                    matrix4d xformOp:transform = ( (0, -1, 0, 0), (0.9396926207859084, 0, 0.3420201433256687, 0), (-0.3420201433256687, 0, 0.9396926207859084, 0), (0.15504024258666294, 0, 0.16120001041495655, 1) )
                    uniform token[] xformOpOrder = ["xformOp:transform"]
                }
            }

            def Xform "Leaf_r3_i0"
            {
                def Cylinder "Petiole"
                {
                    uniform token axis = "Z"
                    double height = 0.033872094
                    rel material:binding = </World/Plant_1/Materials/Leaf>
                    double radius = 0.002772691
                    matrix4d xformOp:transform = ( (0, 1, 0, 0), (-0.3420201433256687, 0, 0.9396926207859084, 0), (0.9396926207859084, 0, 0.3420201433256687, 0), (0.01591467839118332, 0, 0.09423271222231026, 1) )
                    uniform token[] xformOpOrder = ["xformOp:transform"]
                }

                def Cylinder "Rachis"
                {
                    uniform token axis = "Z"
                    double height = 0.08928219
                    rel material:binding = </World/Plant_1/Materials/Leaf>
                    double radius = 0.0016636145999999999
                    matrix4d xformOp:transform = ( (0, 1, 0, 0), (-0.3420201433256687, 0, 0.9396926207859084, 0), (0.9396926207859084, 0, 0.3420201433256687, 0), (0.07377826433766935, 0, 0.11529333515473532, 1) )
                    uniform token[] xformOpOrder = ["xformOp:transform"]
                }

                def Mesh "Blade_0"
                {
                    int[] faceVertexCounts = [3, 3]
                    int[] faceVertexIndices = [0, 1, 2, 0, 2, 3]
                    rel material:binding = </World/Plant_1/Materials/Leaf>
                    point3f[] points = [(-0.019905075, -0.033175126, 0), (0.019905075, -0.033175126, 0), (0.019905075, 0.033175126, 0), (-0.019905075, 0.033175126, 0)]
                    uniform token subdivisionScheme = "none"
                    matrix4d xformOp:transform = ( (-0.7287394448186828, -0.6847910787717361, 0, 0), (-0.16561313590900145, 0.17624181806439163, 0.9703149544244614, 0), (-0.6644630243886748, 0.7071067811865475, -0.24184476264797528, 0), (0.009785713189594182, 0.023458355535809505, 0.09200195132207846, 1) )
                    uniform token[] xformOpOrder = ["xformOp:transform"]
                }

                def Mesh "Blade_1"
                {
                    int[] faceVertexCounts = [3, 3]
                    int[] faceVertexIndices = [0, 1, 2, 0, 2, 3]
                    rel material:binding = </World/Plant_1/Materials/Leaf>
                    point3f[] points = [(-0.019905075, -0.033175126, 0), (0.019905075, -0.033175126, 0), (0.019905075, 0.033175126, 0), (-0.019905075, 0.033175126, 0)]
                    uniform token subdivisionScheme = "none"
                    matrix4d xformOp:transform = ( (0.7287394448186828, -0.6847910787717361, 0, 0), (-0.16561313590900145, -0.17624181806439163, 0.9703149544244614, 0), (-0.6644630243886748, -0.7071067811865475, -0.24184476264797528, 0), (0.05173462074489689, -0.023458355535809505, 0.10727010503219325, 1) )
                    uniform token[] xformOpOrder = ["xformOp:transform"]
                }

                def Mesh "Blade_2"
                {
                    int[] faceVertexCounts = [3, 3]
                    int[] faceVertexIndices = [0, 1, 2, 0, 2, 3]
                    rel material:binding = </World/Plant_1/Materials/Leaf>
                    point3f[] points = [(-0.019905075, -0.033175126, 0), (0.019905075, -0.033175126, 0), (0.019905075, 0.033175126, 0), (-0.019905075, 0.033175126, 0)]
                    uniform token subdivisionScheme = "none"
                    matrix4d xformOp:transform = ( (0, -1, 0, 0), (0.9396926207859084, 0, 0.3420201433256687, 0), (-0.3420201433256687, 0, 0.9396926207859084, 0), (0.11572717189297207, 0, 0.1305614888648501, 1) )
                    uniform token[] xformOpOrder = ["xformOp:transform"]
                }
            }

            def Xform "Leaf_r0_i0"
            {
                def Cylinder "Petiole"
                {
                    uniform token axis = "Z"
                    double height = 0.0140959285
                    rel material:binding = </World/Plant_1/Materials/Leaf>
                    double radius = 0.0013708973
                    matrix4d xformOp:transform = ( (-1.2246467991473532e-16, -1, 0, 0), (0, 0, 1, 0), (-1, 1.2246467991473532e-16, 0, 0), (-0.00704796425, 8.631266859267476e-19, 0.009268469, 1) )
                    uniform token[] xformOpOrder = ["xformOp:transform"]
                }

                def Cylinder "Rachis"
                {
                    uniform token axis = "Z"
                    double height = 0.0001
                    rel material:binding = </World/Plant_1/Materials/Leaf>
                    double radius = 0.0008225383799999999
                    matrix4d xformOp:transform = ( (-1.2246467991473532e-16, -1, 0, 0), (0, 0, 1, 0), (-1, 1.2246467991473532e-16, 0, 0), (-0.0141459285, 1.732376605849232e-18, 0.009268469, 1) )
                    uniform token[] xformOpOrder = ["xformOp:transform"]
                }

                def Mesh "Blade_0"
                {
                    int[] faceVertexCounts = [3, 3]
                    int[] faceVertexIndices = [0, 1, 2, 0, 2, 3]
                    rel material:binding = </World/Plant_1/Materials/Leaf>
                    point3f[] points = [(-0.004493643, -0.0074894046, 0), (0.004493643, -0.0074894046, 0), (0.004493643, 0.0074894046, 0), (-0.004493643, 0.0074894046, 0)]
                    uniform token subdivisionScheme = "none"
                    matrix4d xformOp:transform = ( (0, -1, 0, 0), (1, 0, -0, 0), (0, 0, 1, 0), (-0.0141959285, 1.7384998398449687e-18, 0.009268469, 1) )
                    uniform token[] xformOpOrder = ["xformOp:transform"]
                }
            }

            def Xform "Leaf_r0_i1"
            {
                def Cylinder "Petiole"
                {
                    uniform token axis = "Z"
                    double height = 0.0140959285
                    rel material:binding = </World/Plant_1/Materials/Leaf>
                    double radius = 0.0013708973
                    matrix4d xformOp:transform = ( (0, 1, 0, 0), (0, 0, 1, 0), (1, 0, 0, 0), (0.00704796425, 0, 0.009268469, 1) )
                    uniform token[] xformOpOrder = ["xformOp:transform"]
                }

                def Cylinder "Rachis"
                {
                    uniform token axis = "Z"
                    double height = 0.0001
                    rel material:binding = </World/Plant_1/Materials/Leaf>
                    double radius = 0.0008225383799999999
                    matrix4d xformOp:transform = ( (0, 1, 0, 0), (0, 0, 1, 0), (1, 0, 0, 0), (0.0141459285, 0, 0.009268469, 1) )
                    uniform token[] xformOpOrder = ["xformOp:transform"]
                }

                def Mesh "Blade_0"
                {
                    int[] faceVertexCounts = [3, 3]
                    int[] faceVertexIndices = [0, 1, 2, 0, 2, 3]
                    rel material:binding = </World/Plant_1/Materials/Leaf>
                    point3f[] points = [(-0.004493643, -0.0074894046, 0), (0.004493643, -0.0074894046, 0), (0.004493643, 0.0074894046, 0), (-0.004493643, 0.0074894046, 0)]
                    uniform token subdivisionScheme = "none"
                    matrix4d xformOp:transform = ( (0, -1, 0, 0), (1, 0, -0, 0), (0, 0, 1, 0), (0.0141959285, 0, 0.009268469, 1) )
                    uniform token[] xformOpOrder = ["xformOp:transform"]
                }
            }

            def Xform "Leaf_r1_i0"
            {
                def Cylinder "Petiole"
                {
                    uniform token axis = "Z"
                    double height = 0.02696257
                    rel material:binding = </World/Plant_1/Materials/Leaf>
                    double radius = 0.0023083365
                    matrix4d xformOp:transform = ( (-1, 6.123233995736766e-17, 0, 0), (0, -0, 1, 0), (6.123233995736766e-17, 1, 0, 0), (8.254906261821613e-19, 0.013481285, 0.038654171, 1) )
                    uniform token[] xformOpOrder = ["xformOp:transform"]
                }

                def Cylinder "Rachis"
                {
                    uniform token axis = "Z"
                    double height = 0.032077327
                    rel material:binding = </World/Plant_1/Materials/Leaf>
                    double radius = 0.0013850019
                    matrix4d xformOp:transform = ( (-1, 6.123233995736766e-17, 0, 0), (0, -0, 1, 0), (6.123233995736766e-17, 1, 0, 0), (2.633066148258147e-18, 0.0430012335, 0.038654171, 1) )
                    uniform token[] xformOpOrder = ["xformOp:transform"]
                }

                def Mesh "Blade_0"
                {
                    int[] faceVertexCounts = [3, 3]
                    int[] faceVertexIndices = [0, 1, 2, 0, 2, 3]
                    rel material:binding = </World/Plant_1/Materials/Leaf>
                    point3f[] points = [(-0.011586252, -0.019310419, 0), (0.011586252, -0.019310419, 0), (0.011586252, 0.019310419, 0), (-0.011586252, 0.019310419, 0)]
                    uniform token subdivisionScheme = "none"
                    matrix4d xformOp:transform = ( (0.7071067811865476, -0.7071067811865475, 0, 0), (0, 0, 1, 0), (-0.7071067811865475, -0.7071067811865476, 0, 0), (-0.01365452840025364, 0.013308041599746358, 0.038654171, 1) )
                    uniform token[] xformOpOrder = ["xformOp:transform"]
                }

                def Mesh "Blade_1"
                {
                    int[] faceVertexCounts = [3, 3]
                    int[] faceVertexIndices = [0, 1, 2, 0, 2, 3]
                    rel material:binding = </World/Plant_1/Materials/Leaf>
                    point3f[] points = [(-0.011586252, -0.019310419, 0), (0.011586252, -0.019310419, 0), (0.011586252, 0.019310419, 0), (-0.011586252, 0.019310419, 0)]
                    uniform token subdivisionScheme = "none"
                    matrix4d xformOp:transform = ( (0, -1, 0, 0), (1, 0, -0, 0), (0, 0, 1, 0), (3.6151510441519716e-18, 0.05903989700000001, 0.038654171, 1) )
                    uniform token[] xformOpOrder = ["xformOp:transform"]
                }
            }

            def Xform "Leaf_r1_i1"
            {
                def Cylinder "Petiole"
                {
                    uniform token axis = "Z"
                    double height = 0.02696257
                    rel material:binding = </World/Plant_1/Materials/Leaf>
                    double radius = 0.0023083365
                    matrix4d xformOp:transform = ( (1, -1.8369701987210297e-16, 0, 0), (0, 0, 1, 0), (-1.8369701987210297e-16, -1, 0, 0), (-2.476471878546484e-18, -0.013481285, 0.038654171, 1) )
                    uniform token[] xformOpOrder = ["xformOp:transform"]
                }

                def Cylinder "Rachis"
                {
                    uniform token axis = "Z"
                    double height = 0.032077327
                    rel material:binding = </World/Plant_1/Materials/Leaf>
                    double radius = 0.0013850019
                    matrix4d xformOp:transform = ( (1, -1.8369701987210297e-16, 0, 0), (0, 0, 1, 0), (-1.8369701987210297e-16, -1, 0, 0), (-7.89919844477444e-18, -0.0430012335, 0.038654171, 1) )
                    uniform token[] xformOpOrder = ["xformOp:transform"]
                }

                def Mesh "Blade_0"
                {
                    int[] faceVertexCounts = [3, 3]
                    int[] faceVertexIndices = [0, 1, 2, 0, 2, 3]
                    rel material:binding = </World/Plant_1/Materials/Leaf>
                    point3f[] points = [(-0.011586252, -0.019310419, 0), (0.011586252, -0.019310419, 0), (0.011586252, 0.019310419, 0), (-0.011586252, 0.019310419, 0)]
                    uniform token subdivisionScheme = "none"
                    matrix4d xformOp:transform = ( (-0.7071067811865475, 0.7071067811865476, 0, 0), (0, -0, 1, 0), (0.7071067811865476, 0.7071067811865475, 0, 0), (0.013654528400253638, -0.01330804159974636, 0.038654171, 1) )
                    uniform token[] xformOpOrder = ["xformOp:transform"]
                }

                def Mesh "Blade_1"
                {
                    int[] faceVertexCounts = [3, 3]
                    int[] faceVertexIndices = [0, 1, 2, 0, 2, 3]
                    rel material:binding = </World/Plant_1/Materials/Leaf>
                    point3f[] points = [(-0.011586252, -0.019310419, 0), (0.011586252, -0.019310419, 0), (0.011586252, 0.019310419, 0), (-0.011586252, 0.019310419, 0)]
                    uniform token subdivisionScheme = "none"
                    matrix4d xformOp:transform = ( (0, -1, 0, 0), (1, 0, -0, 0), (0, 0, 1, 0), (-1.0845453132455913e-17, -0.05903989700000001, 0.038654171, 1) )
                    uniform token[] xformOpOrder = ["xformOp:transform"]
                }
            }

            def Xform "Leaf_r2_i0"
            {
                def Cylinder "Petiole"
                {
                    uniform token axis = "Z"
                    double height = 0.034375235
                    rel material:binding = </World/Plant_1/Materials/Leaf>
                    double radius = 0.002805732
                    matrix4d xformOp:transform = ( (-1.2246467991473532e-16, -1, 0, 0), (0.3420201433256687, -4.188538737676992e-17, 0.9396926207859084, 0), (-0.9396926207859084, 1.1507915602278503e-16, 0.3420201433256687, 0), (-0.016151077333640743, 1.97793651594245e-18, 0.07739671840077678, 1) )
                    uniform token[] xformOpOrder = ["xformOp:transform"]
                }

                def Cylinder "Rachis"
                {
                    uniform token axis = "Z"
                    double height = 0.09651485
                    rel material:binding = </World/Plant_1/Materials/Leaf>
                    double radius = 0.0016834392
                    matrix4d xformOp:transform = ( (-1.2246467991473532e-16, -1, 0, 0), (0.3420201433256687, -4.188538737676992e-17, 0.9396926207859084, 0), (-0.9396926207859084, 1.1507915602278503e-16, 0.3420201433256687, 0), (-0.07764930083791091, 9.509296772717746e-18, 0.09978024121658124, 1) )
                    uniform token[] xformOpOrder = ["xformOp:transform"]
                }

                def Mesh "Blade_0"
                {
                    int[] faceVertexCounts = [3, 3]
                    int[] faceVertexIndices = [0, 1, 2, 0, 2, 3]
                    rel material:binding = </World/Plant_1/Materials/Leaf>
                    point3f[] points = [(-0.020760683, -0.034601137, 0), (0.020760683, -0.034601137, 0), (0.020760683, 0.034601137, 0), (-0.020760683, 0.034601137, 0)]
                    uniform token subdivisionScheme = "none"
                    matrix4d xformOp:transform = ( (0.7287394448186829, 0.684791078771736, -0, 0), (0.16561313590900142, -0.17624181806439165, 0.9703149544244614, 0), (0.6644630243886747, -0.7071067811865476, -0.24184476264797528, 0), (-0.009310977873105575, -0.024466699307426003, 0.07490712579772166, 1) )
                    uniform token[] xformOpOrder = ["xformOp:transform"]
                }

                def Mesh "Blade_1"
                {
                    int[] faceVertexCounts = [3, 3]
                    int[] faceVertexIndices = [0, 1, 2, 0, 2, 3]
                    rel material:binding = </World/Plant_1/Materials/Leaf>
                    point3f[] points = [(-0.020760683, -0.034601137, 0), (0.020760683, -0.034601137, 0), (0.020760683, 0.034601137, 0), (-0.020760683, 0.034601137, 0)]
                    uniform token subdivisionScheme = "none"
                    matrix4d xformOp:transform = ( (-0.7287394448186827, 0.6847910787717362, 0, 0), (0.16561313590900148, 0.1762418180643916, 0.9703149544244614, 0), (0.6644630243886749, 0.7071067811865474, -0.24184476264797528, 0), (-0.05465812404373499, 0.02446669930742601, 0.09141213721274936, 1) )
                    uniform token[] xformOpOrder = ["xformOp:transform"]
                }

                def Mesh "Blade_2"
                {
                    int[] faceVertexCounts = [3, 3]
                    int[] faceVertexIndices = [0, 1, 2, 0, 2, 3]
                    rel material:binding = </World/Plant_1/Materials/Leaf>
                    point3f[] points = [(-0.020760683, -0.034601137, 0), (0.020760683, -0.034601137, 0), (0.020760683, 0.034601137, 0), (-0.020760683, 0.034601137, 0)]
                    uniform token subdivisionScheme = "none"
                    matrix4d xformOp:transform = ( (1.224646799147353e-16, 1, -0, 0), (-0.9396926207859084, 1.15079156022785e-16, 0.3420201433256687, 0), (0.3420201433256687, -4.188538737676991e-17, 0.9396926207859084, 0), (-0.12299644700854032, 1.5062720513550593e-17, 0.11628525263160895, 1) )
                    uniform token[] xformOpOrder = ["xformOp:transform"]
                }
            }
        }

        def Xform "Trusses"
        {
            def Xform "Truss_r6_i0"
            {
                def Cylinder "Pedicel"
                {
                    uniform token axis = "Z"
                    double height = 0.012015442
                    rel material:binding = </World/Plant_1/Materials/Pedicel>
                    double radius = 0.00075
                    matrix4d xformOp:transform = ( (-0.9659258262890683, -0.25881904510252085, 0, 0), (0.040488218862836246, -0.15110408990407342, 0.9876883405951378, 0), (-0.25563255317172695, 0.9540336765054371, 0.15643446504023092, 0), (-0.0015357690579734006, 0.005731568153048921, 0.15280881662074597, 1) )
                    uniform token[] xformOpOrder = ["xformOp:transform"]
                }

                def Sphere "Fruit_0"
                {
                    rel material:binding = </World/Plant_1/Materials/Fruit>
                    double radius = 0.005007721
                    matrix4d xformOp:transform = ( (1, 0, 0, 0), (0, 1, 0, 0), (0, 0, 1, 0), (-0.0015357690579734006, 0.005731568153048921, 0.15280881662074597, 1) )
                    uniform token[] xformOpOrder = ["xformOp:transform"]
                }
            }
        }
    }
}

